Workbook

Sheet Summary
A1: legalworkflows delivery plan - status
A2: Every count here is a live COUNTIF/COUNTIFS over the Tickets sheet. Change a status there and these follow.
A3: Sources: docs/delivery-plan/backlog.csv for the register, docs/delivery-plan/v2/status.csv for the statuses. Rebuild with docs/delivery-plan/v2/build-status-workbook.py.
A5: Headline
A6: Measure | B6: Tickets | C6: Share
A7: Total tickets | B7: =COUNTA(Tickets!$E$2:$E$125)
A8: Complete (Done) | B8: =COUNTIF(Tickets!$E$2:$E$125,"Done") | C8: =IFERROR(B8/$B$7,0)
A9: Active (In progress) | B9: =COUNTIF(Tickets!$E$2:$E$125,"In progress") | C9: =IFERROR(B9/$B$7,0)
A10: Remaining (To do) | B10: =COUNTIF(Tickets!$E$2:$E$125,"To do") | C10: =IFERROR(B10/$B$7,0)
A11: Deferred | B11: =COUNTIF(Tickets!$E$2:$E$125,"Deferred") | C11: =IFERROR(B11/$B$7,0)
A12: Closed without delivery | B12: =COUNTIF(Tickets!$E$2:$E$125,"Superseded")+COUNTIF(Tickets!$E$2:$E$125,"Won't do") | C12: =IFERROR(B12/$B$7,0)
A14: By phase
A15: Phase | B15: Done | C15: In progress | D15: To do | E15: Deferred | F15: Superseded | G15: Won't do | H15: Total | I15: % done
A16: Phase 1 - Extraction | B16: =COUNTIFS(Tickets!$G$2:$G$125,$A16,Tickets!$E$2:$E$125,B$15) | C16: =COUNTIFS(Tickets!$G$2:$G$125,$A16,Tickets!$E$2:$E$125,C$15) | D16: =COUNTIFS(Tickets!$G$2:$G$125,$A16,Tickets!$E$2:$E$125,D$15) | E16: =COUNTIFS(Tickets!$G$2:$G$125,$A16,Tickets!$E$2:$E$125,E$15) | F16: =COUNTIFS(Tickets!$G$2:$G$125,$A16,Tickets!$E$2:$E$125,F$15) | G16: =COUNTIFS(Tickets!$G$2:$G$125,$A16,Tickets!$E$2:$E$125,G$15) | H16: =SUM(B16:G16) | I16: =IFERROR(B16/H16,0)
A17: Phase 2 - Infrastructure | B17: =COUNTIFS(Tickets!$G$2:$G$125,$A17,Tickets!$E$2:$E$125,B$15) | C17: =COUNTIFS(Tickets!$G$2:$G$125,$A17,Tickets!$E$2:$E$125,C$15) | D17: =COUNTIFS(Tickets!$G$2:$G$125,$A17,Tickets!$E$2:$E$125,D$15) | E17: =COUNTIFS(Tickets!$G$2:$G$125,$A17,Tickets!$E$2:$E$125,E$15) | F17: =COUNTIFS(Tickets!$G$2:$G$125,$A17,Tickets!$E$2:$E$125,F$15) | G17: =COUNTIFS(Tickets!$G$2:$G$125,$A17,Tickets!$E$2:$E$125,G$15) | H17: =SUM(B17:G17) | I17: =IFERROR(B17/H17,0)
A18: Phase 3 - Production Ready | B18: =COUNTIFS(Tickets!$G$2:$G$125,$A18,Tickets!$E$2:$E$125,B$15) | C18: =COUNTIFS(Tickets!$G$2:$G$125,$A18,Tickets!$E$2:$E$125,C$15) | D18: =COUNTIFS(Tickets!$G$2:$G$125,$A18,Tickets!$E$2:$E$125,D$15) | E18: =COUNTIFS(Tickets!$G$2:$G$125,$A18,Tickets!$E$2:$E$125,E$15) | F18: =COUNTIFS(Tickets!$G$2:$G$125,$A18,Tickets!$E$2:$E$125,F$15) | G18: =COUNTIFS(Tickets!$G$2:$G$125,$A18,Tickets!$E$2:$E$125,G$15) | H18: =SUM(B18:G18) | I18: =IFERROR(B18/H18,0)
A19: Phase 4 - Self-hosted platform | B19: =COUNTIFS(Tickets!$G$2:$G$125,$A19,Tickets!$E$2:$E$125,B$15) | C19: =COUNTIFS(Tickets!$G$2:$G$125,$A19,Tickets!$E$2:$E$125,C$15) | D19: =COUNTIFS(Tickets!$G$2:$G$125,$A19,Tickets!$E$2:$E$125,D$15) | E19: =COUNTIFS(Tickets!$G$2:$G$125,$A19,Tickets!$E$2:$E$125,E$15) | F19: =COUNTIFS(Tickets!$G$2:$G$125,$A19,Tickets!$E$2:$E$125,F$15) | G19: =COUNTIFS(Tickets!$G$2:$G$125,$A19,Tickets!$E$2:$E$125,G$15) | H19: =SUM(B19:G19) | I19: =IFERROR(B19/H19,0)
A20: All | B20: =SUM(B16:B19) | C20: =SUM(C16:C19) | D20: =SUM(D16:D19) | E20: =SUM(E16:E19) | F20: =SUM(F16:F19) | G20: =SUM(G16:G19) | H20: =SUM(H16:H19) | I20: =IFERROR(B20/H20,0)
A22: By sprint
A23: Sprint | B23: Done | C23: In progress | D23: To do | E23: Deferred | F23: Superseded | G23: Won't do | H23: Total | I23: % done
A24: Sprint 1 | B24: =COUNTIFS(Tickets!$H$2:$H$125,$A24,Tickets!$E$2:$E$125,B$23) | C24: =COUNTIFS(Tickets!$H$2:$H$125,$A24,Tickets!$E$2:$E$125,C$23) | D24: =COUNTIFS(Tickets!$H$2:$H$125,$A24,Tickets!$E$2:$E$125,D$23) | E24: =COUNTIFS(Tickets!$H$2:$H$125,$A24,Tickets!$E$2:$E$125,E$23) | F24: =COUNTIFS(Tickets!$H$2:$H$125,$A24,Tickets!$E$2:$E$125,F$23) | G24: =COUNTIFS(Tickets!$H$2:$H$125,$A24,Tickets!$E$2:$E$125,G$23) | H24: =SUM(B24:G24) | I24: =IFERROR(B24/H24,0)
A25: Sprint 2 | B25: =COUNTIFS(Tickets!$H$2:$H$125,$A25,Tickets!$E$2:$E$125,B$23) | C25: =COUNTIFS(Tickets!$H$2:$H$125,$A25,Tickets!$E$2:$E$125,C$23) | D25: =COUNTIFS(Tickets!$H$2:$H$125,$A25,Tickets!$E$2:$E$125,D$23) | E25: =COUNTIFS(Tickets!$H$2:$H$125,$A25,Tickets!$E$2:$E$125,E$23) | F25: =COUNTIFS(Tickets!$H$2:$H$125,$A25,Tickets!$E$2:$E$125,F$23) | G25: =COUNTIFS(Tickets!$H$2:$H$125,$A25,Tickets!$E$2:$E$125,G$23) | H25: =SUM(B25:G25) | I25: =IFERROR(B25/H25,0)
A26: Sprint 3 | B26: =COUNTIFS(Tickets!$H$2:$H$125,$A26,Tickets!$E$2:$E$125,B$23) | C26: =COUNTIFS(Tickets!$H$2:$H$125,$A26,Tickets!$E$2:$E$125,C$23) | D26: =COUNTIFS(Tickets!$H$2:$H$125,$A26,Tickets!$E$2:$E$125,D$23) | E26: =COUNTIFS(Tickets!$H$2:$H$125,$A26,Tickets!$E$2:$E$125,E$23) | F26: =COUNTIFS(Tickets!$H$2:$H$125,$A26,Tickets!$E$2:$E$125,F$23) | G26: =COUNTIFS(Tickets!$H$2:$H$125,$A26,Tickets!$E$2:$E$125,G$23) | H26: =SUM(B26:G26) | I26: =IFERROR(B26/H26,0)
A27: Sprint 4 | B27: =COUNTIFS(Tickets!$H$2:$H$125,$A27,Tickets!$E$2:$E$125,B$23) | C27: =COUNTIFS(Tickets!$H$2:$H$125,$A27,Tickets!$E$2:$E$125,C$23) | D27: =COUNTIFS(Tickets!$H$2:$H$125,$A27,Tickets!$E$2:$E$125,D$23) | E27: =COUNTIFS(Tickets!$H$2:$H$125,$A27,Tickets!$E$2:$E$125,E$23) | F27: =COUNTIFS(Tickets!$H$2:$H$125,$A27,Tickets!$E$2:$E$125,F$23) | G27: =COUNTIFS(Tickets!$H$2:$H$125,$A27,Tickets!$E$2:$E$125,G$23) | H27: =SUM(B27:G27) | I27: =IFERROR(B27/H27,0)
A28: Sprint 5 | B28: =COUNTIFS(Tickets!$H$2:$H$125,$A28,Tickets!$E$2:$E$125,B$23) | C28: =COUNTIFS(Tickets!$H$2:$H$125,$A28,Tickets!$E$2:$E$125,C$23) | D28: =COUNTIFS(Tickets!$H$2:$H$125,$A28,Tickets!$E$2:$E$125,D$23) | E28: =COUNTIFS(Tickets!$H$2:$H$125,$A28,Tickets!$E$2:$E$125,E$23) | F28: =COUNTIFS(Tickets!$H$2:$H$125,$A28,Tickets!$E$2:$E$125,F$23) | G28: =COUNTIFS(Tickets!$H$2:$H$125,$A28,Tickets!$E$2:$E$125,G$23) | H28: =SUM(B28:G28) | I28: =IFERROR(B28/H28,0)
A29: Sprint 6 | B29: =COUNTIFS(Tickets!$H$2:$H$125,$A29,Tickets!$E$2:$E$125,B$23) | C29: =COUNTIFS(Tickets!$H$2:$H$125,$A29,Tickets!$E$2:$E$125,C$23) | D29: =COUNTIFS(Tickets!$H$2:$H$125,$A29,Tickets!$E$2:$E$125,D$23) | E29: =COUNTIFS(Tickets!$H$2:$H$125,$A29,Tickets!$E$2:$E$125,E$23) | F29: =COUNTIFS(Tickets!$H$2:$H$125,$A29,Tickets!$E$2:$E$125,F$23) | G29: =COUNTIFS(Tickets!$H$2:$H$125,$A29,Tickets!$E$2:$E$125,G$23) | H29: =SUM(B29:G29) | I29: =IFERROR(B29/H29,0)
A30: Sprint 7 | B30: =COUNTIFS(Tickets!$H$2:$H$125,$A30,Tickets!$E$2:$E$125,B$23) | C30: =COUNTIFS(Tickets!$H$2:$H$125,$A30,Tickets!$E$2:$E$125,C$23) | D30: =COUNTIFS(Tickets!$H$2:$H$125,$A30,Tickets!$E$2:$E$125,D$23) | E30: =COUNTIFS(Tickets!$H$2:$H$125,$A30,Tickets!$E$2:$E$125,E$23) | F30: =COUNTIFS(Tickets!$H$2:$H$125,$A30,Tickets!$E$2:$E$125,F$23) | G30: =COUNTIFS(Tickets!$H$2:$H$125,$A30,Tickets!$E$2:$E$125,G$23) | H30: =SUM(B30:G30) | I30: =IFERROR(B30/H30,0)
A31: All | B31: =SUM(B24:B30) | C31: =SUM(C24:C30) | D31: =SUM(D24:D30) | E31: =SUM(E24:E30) | F31: =SUM(F24:F30) | G31: =SUM(G24:G30) | H31: =SUM(H24:H30) | I31: =IFERROR(B31/H31,0)
A33: By component
A34: Component | B34: Done | C34: In progress | D34: To do | E34: Deferred | F34: Superseded | G34: Won't do | H34: Total | I34: % done
A35: Platform | B35: =COUNTIFS(Tickets!$I$2:$I$125,$A35,Tickets!$E$2:$E$125,B$34) | C35: =COUNTIFS(Tickets!$I$2:$I$125,$A35,Tickets!$E$2:$E$125,C$34) | D35: =COUNTIFS(Tickets!$I$2:$I$125,$A35,Tickets!$E$2:$E$125,D$34) | E35: =COUNTIFS(Tickets!$I$2:$I$125,$A35,Tickets!$E$2:$E$125,E$34) | F35: =COUNTIFS(Tickets!$I$2:$I$125,$A35,Tickets!$E$2:$E$125,F$34) | G35: =COUNTIFS(Tickets!$I$2:$I$125,$A35,Tickets!$E$2:$E$125,G$34) | H35: =SUM(B35:G35) | I35: =IFERROR(B35/H35,0)
A36: Backend | B36: =COUNTIFS(Tickets!$I$2:$I$125,$A36,Tickets!$E$2:$E$125,B$34) | C36: =COUNTIFS(Tickets!$I$2:$I$125,$A36,Tickets!$E$2:$E$125,C$34) | D36: =COUNTIFS(Tickets!$I$2:$I$125,$A36,Tickets!$E$2:$E$125,D$34) | E36: =COUNTIFS(Tickets!$I$2:$I$125,$A36,Tickets!$E$2:$E$125,E$34) | F36: =COUNTIFS(Tickets!$I$2:$I$125,$A36,Tickets!$E$2:$E$125,F$34) | G36: =COUNTIFS(Tickets!$I$2:$I$125,$A36,Tickets!$E$2:$E$125,G$34) | H36: =SUM(B36:G36) | I36: =IFERROR(B36/H36,0)
A37: Frontend | B37: =COUNTIFS(Tickets!$I$2:$I$125,$A37,Tickets!$E$2:$E$125,B$34) | C37: =COUNTIFS(Tickets!$I$2:$I$125,$A37,Tickets!$E$2:$E$125,C$34) | D37: =COUNTIFS(Tickets!$I$2:$I$125,$A37,Tickets!$E$2:$E$125,D$34) | E37: =COUNTIFS(Tickets!$I$2:$I$125,$A37,Tickets!$E$2:$E$125,E$34) | F37: =COUNTIFS(Tickets!$I$2:$I$125,$A37,Tickets!$E$2:$E$125,F$34) | G37: =COUNTIFS(Tickets!$I$2:$I$125,$A37,Tickets!$E$2:$E$125,G$34) | H37: =SUM(B37:G37) | I37: =IFERROR(B37/H37,0)
A38: Word Add-in | B38: =COUNTIFS(Tickets!$I$2:$I$125,$A38,Tickets!$E$2:$E$125,B$34) | C38: =COUNTIFS(Tickets!$I$2:$I$125,$A38,Tickets!$E$2:$E$125,C$34) | D38: =COUNTIFS(Tickets!$I$2:$I$125,$A38,Tickets!$E$2:$E$125,D$34) | E38: =COUNTIFS(Tickets!$I$2:$I$125,$A38,Tickets!$E$2:$E$125,E$34) | F38: =COUNTIFS(Tickets!$I$2:$I$125,$A38,Tickets!$E$2:$E$125,F$34) | G38: =COUNTIFS(Tickets!$I$2:$I$125,$A38,Tickets!$E$2:$E$125,G$34) | H38: =SUM(B38:G38) | I38: =IFERROR(B38/H38,0)
A39: Infrastructure | B39: =COUNTIFS(Tickets!$I$2:$I$125,$A39,Tickets!$E$2:$E$125,B$34) | C39: =COUNTIFS(Tickets!$I$2:$I$125,$A39,Tickets!$E$2:$E$125,C$34) | D39: =COUNTIFS(Tickets!$I$2:$I$125,$A39,Tickets!$E$2:$E$125,D$34) | E39: =COUNTIFS(Tickets!$I$2:$I$125,$A39,Tickets!$E$2:$E$125,E$34) | F39: =COUNTIFS(Tickets!$I$2:$I$125,$A39,Tickets!$E$2:$E$125,F$34) | G39: =COUNTIFS(Tickets!$I$2:$I$125,$A39,Tickets!$E$2:$E$125,G$34) | H39: =SUM(B39:G39) | I39: =IFERROR(B39/H39,0)
A40: Integration | B40: =COUNTIFS(Tickets!$I$2:$I$125,$A40,Tickets!$E$2:$E$125,B$34) | C40: =COUNTIFS(Tickets!$I$2:$I$125,$A40,Tickets!$E$2:$E$125,C$34) | D40: =COUNTIFS(Tickets!$I$2:$I$125,$A40,Tickets!$E$2:$E$125,D$34) | E40: =COUNTIFS(Tickets!$I$2:$I$125,$A40,Tickets!$E$2:$E$125,E$34) | F40: =COUNTIFS(Tickets!$I$2:$I$125,$A40,Tickets!$E$2:$E$125,F$34) | G40: =COUNTIFS(Tickets!$I$2:$I$125,$A40,Tickets!$E$2:$E$125,G$34) | H40: =SUM(B40:G40) | I40: =IFERROR(B40/H40,0)
A41: All | B41: =SUM(B35:B40) | C41: =SUM(C35:C40) | D41: =SUM(D35:D40) | E41: =SUM(E35:E40) | F41: =SUM(F35:F40) | G41: =SUM(G35:G40) | H41: =SUM(H35:H40) | I41: =IFERROR(B41/H41,0)
A43: By issue type
A44: Issue Type | B44: Done | C44: In progress | D44: To do | E44: Deferred | F44: Superseded | G44: Won't do | H44: Total | I44: % done
A45: Epic | B45: =COUNTIFS(Tickets!$C$2:$C$125,$A45,Tickets!$E$2:$E$125,B$44) | C45: =COUNTIFS(Tickets!$C$2:$C$125,$A45,Tickets!$E$2:$E$125,C$44) | D45: =COUNTIFS(Tickets!$C$2:$C$125,$A45,Tickets!$E$2:$E$125,D$44) | E45: =COUNTIFS(Tickets!$C$2:$C$125,$A45,Tickets!$E$2:$E$125,E$44) | F45: =COUNTIFS(Tickets!$C$2:$C$125,$A45,Tickets!$E$2:$E$125,F$44) | G45: =COUNTIFS(Tickets!$C$2:$C$125,$A45,Tickets!$E$2:$E$125,G$44) | H45: =SUM(B45:G45) | I45: =IFERROR(B45/H45,0)
...

Sheet Tickets
A1: Issue Id | B1: Parent Id | C1: Issue Type | D1: Summary | E1: Status | F1: Status note | G1: Phase | H1: Sprint | I1: Component | J1: Priority | K1: Repo | L1: Labels | M1: Acceptance Criteria | N1: Description
A2: 2001 | C2: Epic | D2: Foundation: private repository and upstream tracking | E2: In progress | F2: Rolled up from 2 children: 1 done, 1 in progress. | G2: Phase 1 - Extraction | H2: Sprint 1 | I2: Platform | J2: Highest | K2: legal-workflow-service | L2: foundation | M2: Private repo exists and is protected; a clean clone builds; upstream-main mirrors upstream and merges fast-forward. | N2: Stand up the private repository extracted from matchamfraser/legalworkflows at commit 8b3466f, with the remote topology that keeps upstream security fixes mergeable. The fork is currently at exact parity with upstream - 581 commits, no divergence - so this is the cheapest moment to get the structure right.
A3: 2002 | B3: 2001 | C3: Story | D3: Extract into a private repository with history intact | E3: Done | F3: Rolled up from 4 children: 4 done. | G3: Phase 1 - Extraction | H3: Sprint 1 | I3: Platform | J3: Highest | K3: legal-workflow-service | L3: foundation | M3: git log on backend/src/app.ts shows pre-extraction commits; npm ci and npm run build pass from a clean clone. | N3: Clone the full tree with history rather than copying files. History is what makes upstream merges possible and is the cleanest record of what changed and when, which AGPL section 5(a) asks you to state. Do NOT squash or re-init.
A4: 2003 | B4: 2002 | C4: Sub-task | D4: Clone with full history and rewire remotes | E4: Done | F4: repository exists with history | G4: Phase 1 - Extraction | H4: Sprint 1 | I4: Platform | J4: Highest | K4: legal-workflow-service | L4: foundation | M4: git remote -v shows all three; git log --oneline | wc -l returns 581. | N4: git clone the existing fork, then: rename origin to fork, add upstream = Open-Legal-Products/legalworkflows, add origin = the new private repo. Three remotes, each with one job. Push main to the new origin.
A5: 2004 | B5: 2002 | C5: Sub-task | D5: Create the protected upstream-main mirror branch | E5: Done | F5: upstream-main exists on the remote | G5: Phase 1 - Extraction | H5: Sprint 1 | I5: Platform | J5: Highest | K5: legal-workflow-service | L5: foundation | M5: upstream-main exists on origin; a non-fast-forward push to it is rejected. | N5: Branch upstream-main from upstream/main and push it. Nothing is ever committed to this branch - it exists only as a clean merge base. Protect it to allow fast-forward pushes only, so it cannot drift.
A6: 2005 | B6: 2002 | C6: Sub-task | D6: Configure branch protection and merge rules on main | E6: Done | F6: branch protection set in GitHub settings (plan 4.5) | G6: Phase 1 - Extraction | H6: Sprint 1 | I6: Platform | J6: High | K6: legal-workflow-service | L6: foundation | M6: Direct push to main is rejected; a PR with red CI cannot merge. | N6: Protect main: require a PR, require status checks to pass, require branches up to date before merging, no force push, auto-delete merged branches. Solo development still benefits - this is what makes CI actually gate anything.
A7: 2006 | B7: 2002 | C7: Sub-task | D7: Add fork-specific rules to AGENTS.md | E7: Done | F7: fork rules present in AGENTS.md | G7: Phase 1 - Extraction | H7: Sprint 1 | I7: Platform | J7: High | K7: legal-workflow-service | L7: foundation | M7: AGENTS.md states all four rules; both the developer and Claude Code are bound by them from the first commit. | N7: The repo already carries a strong AGENTS.md. Add a section at the top covering the four constraints specific to this fork: the HTTP-only service boundary to Juralio, the user-visible-only rename rule with its do-not-touch list, the additive-changes-in-new-files merge rule, and the rule that LICENSE is never deleted or altered.
A8: 2007 | B8: 2001 | C8: Story | D8: Establish and prove the upstream merge routine | E8: In progress | F8: Rolled up from 2 children: 1 done, 1 to do. | G8: Phase 1 - Extraction | H8: Sprint 1 | I8: Platform | J8: High | K8: legal-workflow-service | L8: foundation | M8: A documented three-command sync exists and has been run end to end at least once. | N8: Upstream merged 581 commits in roughly four months. A sync routine that is documented and exercised once now is far cheaper than one improvised in six months against a large diff.
A9: 2008 | B9: 2007 | C9: Sub-task | D9: Document and script the upstream sync | E9: Done | F9: docs/upstream-sync.md | G9: Phase 1 - Extraction | H9: Sprint 1 | I9: Platform | J9: High | K9: legal-workflow-service | L9: foundation | M9: docs/upstream-sync.md exists; the routine is reproducible from it alone. | N9: fetch upstream, fast-forward upstream-main, merge upstream-main into main, resolve, test, push. Note the .gitattributes convention already in the repo: package-lock.json is merged as binary deliberately, so conflicts surface explicitly - resolve by taking main's copy and regenerating.
A10: 2009 | B10: 2007 | C10: Sub-task | D10: Run a first upstream merge as a dry run | E10: To do | F10: Never performed in this fork; the "upstream" merges in history are inherited. Value decays as the fork diverges. | G10: Phase 1 - Extraction | H10: Sprint 1 | I10: Platform | J10: Medium | K10: legal-workflow-service | L10: foundation | M10: Merge completes; full backend and frontend suites green afterwards. | N10: Execute the routine before any local divergence exists, so the mechanics are proven while a conflict is impossible. Records a baseline merge commit.
A11: 2010 | C11: Epic | D11: Unblock the build | E11: In progress | F11: Rolled up from 2 children: 1 done, 1 to do. | G11: Phase 1 - Extraction | H11: Sprint 1 | I11: Backend | J11: Highest | K11: legal-workflow-service | L11: blocker | M11: npm ci completes on a filtered network; all 117 backend test files run, not 80. | N11: Two inherited dependencies stop the project dead on a restricted network. Neither is a code defect, both must be cleared before any CI work can be validated. Verified in review: npm ci fails with a 403 today.
A12: 2011 | B12: 2010 | C12: Story | D12: Remove the SheetJS CDN dependency | E12: Done | F12: Rolled up from 2 children: 1 done, 1 won't do. | G12: Phase 1 - Extraction | H12: Sprint 1 | I12: Backend | J12: Highest | K12: legal-workflow-service | L12: blocker | M12: npm ci --prefix backend succeeds behind an egress filter; spreadsheet parsing behaviour is unchanged. | N12: backend/package.json pins xlsx to https://cdn.sheetjs.com/xlsx-0.20.3/xlsx-0.20.3.tgz - a direct vendor tarball, not a registry package. Any proxy or air-gapped runner fails npm ci outright, and Dependabot cannot see it. Only backend/src/lib/spreadsheet.ts imports it.
A13: 2012 | B13: 2011 | C13: Sub-task | D13: Replace xlsx with exceljs in spreadsheet.ts | E13: Won't do | F13: From the delivery plan row that cites it. | G13: Phase 1 - Extraction | H13: Sprint 1 | I13: Backend | J13: Highest | K13: legal-workflow-service | L13: blocker | M13: Existing spreadsheet tests pass unchanged; a sample .xlsx, .xlsm and legacy .xls each produce identical output to the previous implementation. | N13: exceljs is already a frontend dependency, so it is a known quantity. Preserve the current output contract exactly: a cell-addressed markdown table per sheet, using the Excel-formatted display string (cell.w equivalent) so dates and currency reach the model as a human sees them, with cached formula results rather than formulas.
A14: 2013 | B14: 2011 | C14: Sub-task | D14: Verify a clean install and the full backend suite | E14: Done | F14: From the delivery plan row that cites it. | G14: Phase 1 - Extraction | H14: Sprint 1 | I14: Backend | J14: Highest | K14: legal-workflow-service | L14: blocker | M14: npm ci, npm run build and npm test all pass; test file count is 117, not 80. | N14: Confirm the fix on a network that blocks non-registry hosts. Before this ticket, 31 of 117 backend test files cannot be exercised at all.
A15: 2014 | B15: 2010 | C15: Story | D15: Take ownership of the workflow catalogue | E15: To do | F15: Rolled up from 2 children: 2 to do. | G15: Phase 1 - Extraction | H15: Sprint 1 | I15: Backend | J15: High | K15: legal-workflow-service | L15: blocker | M15: The catalogue syncs from a repository you control; upstream renaming or privatising theirs has no effect. | N15: System assistant and tabular-review workflows are not in this tree. A sync job downloads them at runtime from Open-Legal-Products/mike-workflows, and five defaults are hardcoded by key in backend/src/lib/workflowCatalogSource.ts. Product content is therefore controlled by a third party.
A16: 2015 | B16: 2014 | C16: Sub-task | D16: Fork mike-workflows and repoint the sync | E16: To do | F16: Inherited from parent 2014 (to do). | G16: Phase 1 - Extraction | H16: Sprint 1 | I16: Backend | J16: High | K16: legal-workflow-service | L16: blocker | M16: Sync job pulls from the fork; workflows appear in the app; the catalogue repo licence is recorded. | N16: Fork the catalogue repository and set MIKE_WORKFLOWS_REPOSITORY to the fork. Check the catalogue repo's own licence first - it is a separate repository and may not be AGPL. The ingestion code is already hardened with size caps, path validation and timeouts, so this is configuration, not a rewrite.
A17: 2016 | B17: 2014 | C17: Sub-task | D17: Verify catalogue sync end to end | E17: To do | F17: Inherited from parent 2014 (to do). | G17: Phase 1 - Extraction | H17: Sprint 1 | I17: Backend | J17: Medium | K17: legal-workflow-service | L17: blocker | M17: Fresh database reaches a populated workflow catalogue with no manual steps. | N17: Run the sync job against an empty database and confirm the five defaults install, quick actions resolve, and add-ons appear in the catalogue.
A18: 2017 | C18: Epic | D18: CI/CD adaptation | E18: In progress | F18: Rolled up from 2 children: 1 done, 1 in progress. | G18: Phase 1 - Extraction | H18: Sprint 2 | I18: Platform | J18: Highest | K18: legal-workflow-service | L18: ci | M18: CI green on every PR; the security suites are required checks; no workflow fails for reasons unrelated to the code. | N18: Nine of the eleven inherited workflows carry over, one must be deleted because it cannot work on a private repo, and one is optional. The inherited suite is unusually strong - mutation testing, a real-Supabase security suite and a schema drift check - and is worth preserving intact.
A19: 2018 | B19: 2017 | C19: Story | D19: Port the inherited workflows to the private repo | E19: In progress | F19: Rolled up from 5 children: 3 done, 1 in progress, 1 won't do. | G19: Phase 1 - Extraction | H19: Sprint 2 | I19: Platform | J19: Highest | K19: legal-workflow-service | L19: ci | M19: Every retained workflow runs green; deleted and disabled ones are documented with the reason. | N19: Adapt the eleven workflows to the new repo topology and plan constraints.
A20: 2019 | B20: 2018 | C20: Sub-task | D20: Delete scorecard.yml and retarget branch filters | E20: Done | F20: scorecard.yml absent from .github/workflows/ | G20: Phase 1 - Extraction | H20: Sprint 2 | I20: Platform | J20: High | K20: legal-workflow-service | L20: ci | M20: scorecard.yml removed with the reason in the commit message; e2e branch filter verified correct. | N20: scorecard.yml sets publish_results: true against the OpenSSF public API, which only accepts public repositories - it cannot work here. Separately, e2e.yml already filters on [main, upstream-main], which matches the topology from the foundation epic; confirm rather than change.
A21: 2020 | B21: 2018 | C21: Sub-task | D21: Configure Actions secrets and verify the e2e run | E21: In progress | F21: e2e green, but ANTHROPIC_API_KEY is unset so 4 LLM specs — including critical-path "ask a question" — skip every run. Established from the job env block. | G21: Phase 1 - Extraction | H21: Sprint 2 | I21: Platform | J21: High | K21: legal-workflow-service | L21: ci | M21: e2e workflow completes green on a pull request. | N21: Create ANTHROPIC_API_KEY (spend-capped, CI-scoped) for e2e.yml and LOADTEST_AUTH_TOKEN if the k6 job is retained. The e2e workflow boots Supabase, RustFS and Playwright on the runner, so this is the longest feedback loop to prove.
A22: 2021 | B22: 2018 | C22: Sub-task | D22: Enable Dependabot and confirm the advisory gate | E22: Done | F22: .github/dependabot.yml | G22: Phase 1 - Extraction | H22: Sprint 2 | I22: Platform | J22: Medium | K22: legal-workflow-service | L22: ci | M22: Dependabot opens a PR against a seeded outdated dependency; security.yml fails the build on a known advisory. | N22: .github/dependabot.yml already ships. On a private repo, Dependabot alerts and security updates must be enabled explicitly under Settings > Advanced Security. It pairs with security.yml, which fails the build on a high or critical advisory.
A23: 2022 | B23: 2018 | C23: Sub-task | D23: Confirm CodeQL availability on the account plan | E23: Done | F23: .github/workflows/codeql.yml | G23: Phase 1 - Extraction | H23: Sprint 2 | I23: Platform | J23: Medium | K23: legal-workflow-service | L23: ci | M23: codeql.yml either runs green or is disabled with a documented decision. | N23: CodeQL on private repositories requires GitHub Advanced Security on some plans. Establish whether it runs; if not, record the gap and decide whether to buy the capability or accept the loss.
A24: 2023 | B24: 2018 | C24: Sub-task | D24: Disable the Word add-in workflow while the add-in is deferred | E24: Won't do | F24: Plan "Ticket disposition": obsolete — the add-in is not deferred. | G24: Phase 1 - Extraction | H24: Sprint 2 | I24: Platform | J24: Low | K24: legal-workflow-service | L24: ci | M24: Workflow disabled with a comment naming the sprint it should return in. | N24: word-addin.yml runs Playwright against chromium and webkit. The add-in stays in the repo but is out of scope for these 24 weeks, so the job is noise. Disable rather than delete - it is re-enabled when the add-in is picked up.
A25: 2024 | B25: 2017 | C25: Story | D25: Make the security suites required checks | E25: Done | F25: Rolled up from 2 children: 2 done. | G25: Phase 1 - Extraction | H25: Sprint 2 | I25: Platform | J25: Highest | K25: legal-workflow-service | L25: ci,security | M25: A PR cannot merge with any of them red. | N25: These are the gates that catch real damage on a service-role architecture. Protecting the branch without them is theatre.
A26: 2025 | B26: 2024 | C26: Sub-task | D26: Require stack-tests, schema-drift, gitleaks and CI | E26: Done | F26: From the delivery plan row that cites it. | G26: Phase 1 - Extraction | H26: Sprint 2 | I26: Platform | J26: Highest | K26: legal-workflow-service | L26: ci,security | M26: All four are required status checks on main; each has run green at least once. | N26: stack-tests boots a real Supabase and asserts the deny-all RLS firewall holds for anon and authenticated clients - the only backstop for an architecture where the backend runs as service role. schema-drift compares a fresh database against an upgraded one. gitleaks scans full history.
A27: 2026 | B27: 2024 | C27: Sub-task | D27: Keep mutation testing running against the security libs | E27: Done | F27: Inherited from parent 2024 (done). | G27: Phase 1 - Extraction | H27: Sprint 2 | I27: Platform | J27: Medium | K27: legal-workflow-service | L27: ci,security | M27: Mutation workflow runs and its report is retrievable; the scoped file list is unchanged. | N27: Stryker is scoped to access.ts, downloadTokens.ts and chat/citations.ts - the places where a hollow test is dangerous. It runs monthly as a drift check and does not gate merges upstream; keep that posture.
A28: 2027 | C28: Epic | D28: Debranding | E28: Done | F28: Rolled up from 2 children: 2 done. | G28: Phase 1 - Extraction | H28: Sprint 2 | I28: Platform | J28: High | K28: legal-workflow-service | L28: branding | M28: No upstream trademark appears in any user-visible surface; database, env var and module names are unchanged; all suites green. | N28: Strip the upstream trademark from user-visible surfaces while leaving internal identifiers alone. About 260 files mention the name; only a few dozen are user-visible. Renaming database objects, environment variables or the API client buys nothing and guarantees conflicts on every upstream merge.
A29: 2028 | B29: 2027 | C29: Story | D29: Replace user-visible branding in the web app | E29: Done | F29: Rolled up from 5 children: 5 done. | G29: Phase 1 - Extraction | H29: Sprint 2 | I29: Frontend | J29: High | K29: legal-workflow-service | L29: branding | M29: Wordmark, metadata, MFA issuer and user-facing copy all carry the new brand; frontend build and 980 tests green. | N29: Work file by file from the identified list. Do NOT run a repo-wide find-and-replace: it will hit comments, test fixtures, table names and the API client, and unpicking it costs more than doing it properly.
A30: 2029 | B30: 2028 | C30: Sub-task | D30: Replace the wordmark and application metadata | E30: Done | F30: Debranding; npm run trademarks sweeps user-visible surfaces and passes in CI. | G30: Phase 1 - Extraction | H30: Sprint 2 | I30: Frontend | J30: High | K30: legal-workflow-service | L30: branding | M30: Wordmark and OG metadata show the new brand; a shared link preview renders correctly. | N30: frontend/src/app/components/site-logo.tsx carries the wordmark. frontend/src/app/layout.tsx carries the Open Graph siteName and image alt text. Both are rendered to users and to link previews.
A31: 2030 | B31: 2028 | C31: Sub-task | D31: Change the MFA issuer name | E31: Done | F31: MFA issuer name changed; covered by the rebrand checklist (2036). | G31: Phase 1 - Extraction | H31: Sprint 2 | I31: Frontend | J31: High | K31: legal-workflow-service | L31: branding | M31: A newly enrolled TOTP factor shows the new brand in the authenticator app. | N31: settings/security/page.tsx passes the brand to enrollMfa, which becomes the account label inside users' authenticator apps. Changing it after users enrol is disruptive, so it must be right before the first real account exists.
A32: 2031 | B32: 2028 | C32: Sub-task | D32: Update user-facing copy across settings and modals | E32: Done | F32: User-facing copy; covered by the trademark sweep and rebrand checklist. | G32: Phase 1 - Extraction | H32: Sprint 2 | I32: Frontend | J32: Medium | K32: legal-workflow-service | L32: branding | M32: No user-visible string names the upstream product; copy reads naturally with the new name. | N32: settings/personalisation, tabular/AddColumnModal, workflows/WFEditColumnModal, shared/AddUserInput and assistant error text all name the assistant in copy shown to users.
A33: 2032 | B33: 2028 | C33: Sub-task | D33: Replace icon components and image assets | E33: Done | F33: From the delivery plan row that cites it. | G33: Phase 1 - Extraction | H33: Sprint 2 | I33: Frontend | J33: Medium | K33: legal-workflow-service | L33: branding | M33: New mark renders in the app and add-in; upstream screenshots deleted from docs/assets. | N33: MikeIconUI.tsx in shared/ui, chat/mike-icon.tsx, and the marketing images under docs/assets. Keep the component filenames if you are tracking upstream - only the rendered artwork needs to change.
A34: 2033 | B34: 2028 | C34: Sub-task | D34: Update Word add-in surfaces | E34: Done | F34: completed this session | G34: Phase 1 - Extraction | H34: Sprint 2 | I34: Word Add-in | J34: Low | K34: legal-workflow-service | L34: branding | M34: Add-in task pane shows the new brand; typecheck passes. | N34: word-addin WordAddinLogo.tsx is the branded lockup; EditCard.tsx and useWordDoc.ts carry user-facing strings naming the assistant. In scope even though the add-in is not shipped, so the brand is consistent when it is picked up.
A35: 2034 | B35: 2027 | C35: Story | D35: Fix the rename boundary in writing | E35: Done | F35: Rolled up from 2 children: 2 done. | G35: Phase 1 - Extraction | H35: Sprint 2 | I35: Platform | J35: High | K35: legal-workflow-service | L35: branding | M35: The do-not-rename list is in AGENTS.md and has survived one upstream merge. | N35: Without a written rule, the next rename will reach into the database and the merge cost becomes permanent.
A36: 2035 | B36: 2034 | C36: Sub-task | D36: Record the do-not-rename identifiers | E36: Done | F36: do-not-rename table in AGENTS.md fork rule 2 | G36: Phase 1 - Extraction | H36: Sprint 2 | I36: Platform | J36: High | K36: legal-workflow-service | L36: branding | M36: AGENTS.md lists all four with the reasoning; a reviewer can apply the rule without asking. | N36: Four categories stay as they are: the mike_workflows and mike_workflow_assets tables with their 11 indexes and constraints; the MIKE_WORKFLOWS_REPOSITORY, _REF and _TOKEN environment variables; mikeApi.ts, which is 2,837 lines imported across the frontend; and the private package names. Each is invisible to users and expensive to change.
A37: 2036 | B37: 2034 | C37: Sub-task | D37: Verify the rebrand against a full build and suite | E37: Done | F37: completed this session | G37: Phase 1 - Extraction | H37: Sprint 2 | I37: Platform | J37: High | K37: legal-workflow-service | L37: branding | M37: frontend build, 141 test files, backend suite and lint all green; manual pass over every rebranded screen. | N37: A find-and-replace error in this area typically surfaces as a broken import or a failed snapshot rather than a visible bug.
A38: 2037 | C38: Epic | D38: Infrastructure foundation | E38: In progress | F38: Rolled up from 3 children: 1 done, 1 in progress, 1 superseded. | G38: Phase 2 - Infrastructure | H38: Sprint 3 | I38: Infrastructure | J38: Highest | K38: legal-workflow-service | L38: infra | M38: Staging and production both provisioned; schema loaded and drift-checked; secrets generated per environment. | N38: Provision the managed services the platform needs, as code where possible, with staging and production separated from the start. This is client-confidential legal material, so the two environments never share a database, a bucket or a secret.
A39: 2038 | B39: 2037 | C39: Story | D39: Provision Supabase and load the schema | E39: Superseded | F39: Rolled up from 3 children: 3 superseded. | G39: Phase 2 - Infrastructure | H39: Sprint 3 | I39: Infrastructure | J39: Highest | K39: legal-workflow-service | L39: infra | M39: Both environments reach an identical schema; the drift check passes fresh against upgraded. | N39: backend/schema.sql is the complete fresh-install schema at 4,906 lines covering 50 tables; backend/migrations/ holds 85 dated incremental files. A fresh install loads the schema; an existing deployment applies only migrations newer than its recorded version, in filename order.
A40: 2039 | B40: 2038 | C40: Sub-task | D40: Create staging and production Supabase projects | E40: Superseded | F40: Plan disposition made this production-only; Stage 5 removes the Supabase project entirely. | G40: Phase 2 - Infrastructure | H40: Sprint 3 | I40: Infrastructure | J40: Highest | K40: legal-workflow-service | L40: infra | M40: Two projects exist with no shared credentials; access is documented. | N40: Separate projects, separate credentials, separate regions if data residency requires it. Never point staging at production data.
...

Sheet Outstanding
A1: Outstanding work
A2: Every ticket not yet Done, ordered by phase, then sprint, then priority. Deferred, superseded and won't-do tickets are on the Tickets sheet.
A4: Issue Id | B4: Issue Type | C4: Summary | D4: Status | E4: Status note | F4: Phase | G4: Sprint | H4: Component | I4: Priority
A5: 2001 | B5: Epic | C5: Foundation: private repository and upstream tracking | D5: In progress | E5: Rolled up from 2 children: 1 done, 1 in progress. | F5: Phase 1 - Extraction | G5: Sprint 1 | H5: Platform | I5: Highest
A6: 2010 | B6: Epic | C6: Unblock the build | D6: In progress | E6: Rolled up from 2 children: 1 done, 1 to do. | F6: Phase 1 - Extraction | G6: Sprint 1 | H6: Backend | I6: Highest
A7: 2007 | B7: Story | C7: Establish and prove the upstream merge routine | D7: In progress | E7: Rolled up from 2 children: 1 done, 1 to do. | F7: Phase 1 - Extraction | G7: Sprint 1 | H7: Platform | I7: High
A8: 2014 | B8: Story | C8: Take ownership of the workflow catalogue | D8: To do | E8: Rolled up from 2 children: 2 to do. | F8: Phase 1 - Extraction | G8: Sprint 1 | H8: Backend | I8: High
A9: 2015 | B9: Sub-task | C9: Fork mike-workflows and repoint the sync | D9: To do | E9: Inherited from parent 2014 (to do). | F9: Phase 1 - Extraction | G9: Sprint 1 | H9: Backend | I9: High
A10: 2009 | B10: Sub-task | C10: Run a first upstream merge as a dry run | D10: To do | E10: Never performed in this fork; the "upstream" merges in history are inherited. Value decays as the fork diverges. | F10: Phase 1 - Extraction | G10: Sprint 1 | H10: Platform | I10: Medium
A11: 2016 | B11: Sub-task | C11: Verify catalogue sync end to end | D11: To do | E11: Inherited from parent 2014 (to do). | F11: Phase 1 - Extraction | G11: Sprint 1 | H11: Backend | I11: Medium
A12: 2017 | B12: Epic | C12: CI/CD adaptation | D12: In progress | E12: Rolled up from 2 children: 1 done, 1 in progress. | F12: Phase 1 - Extraction | G12: Sprint 2 | H12: Platform | I12: Highest
A13: 2018 | B13: Story | C13: Port the inherited workflows to the private repo | D13: In progress | E13: Rolled up from 5 children: 3 done, 1 in progress, 1 won't do. | F13: Phase 1 - Extraction | G13: Sprint 2 | H13: Platform | I13: Highest
A14: 2020 | B14: Sub-task | C14: Configure Actions secrets and verify the e2e run | D14: In progress | E14: e2e green, but ANTHROPIC_API_KEY is unset so 4 LLM specs — including critical-path "ask a question" — skip every run. Established from the job env block. | F14: Phase 1 - Extraction | G14: Sprint 2 | H14: Platform | I14: High
A15: 2037 | B15: Epic | C15: Infrastructure foundation | D15: In progress | E15: Rolled up from 3 children: 1 done, 1 in progress, 1 superseded. | F15: Phase 2 - Infrastructure | G15: Sprint 3 | H15: Infrastructure | I15: Highest
... A48: 2126 | B48: Sub-task | C48: Update the documentation | D48: To do | E48: Stage 5, added 17 September 2026. | F48: Phase 4 - Self-hosted platform | G48: Sprint 7 | H48: Platform | I48: Medium
A50: Open tickets | B50: =COUNTIF(Tickets!$E$2:$E$125,"In progress")+COUNTIF(Tickets!$E$2:$E$125,"To do")
A51: The rows are a snapshot; the count beside them is live from the Tickets sheet.
